<?xml version="1.0" ?>
<!-- =================================================================================== -->
<!-- |    This document was autogenerated by xacro from kr10r1100sixx.xacro            | -->
<!-- |    EDITING THIS FILE BY HAND IS NOT RECOMMENDED                                 | -->
<!-- =================================================================================== -->
<robot name="kuka_kr10r1100sixx" xmlns:xacro="http://www.ros.org/wiki/xacro">
  <!-- colours based on RAL values given in "FAQ - Colours of robot and robot
       controller", version "KUKA.Tifs | 2010-01-21 |YM| DefaultColorsRobotAndController.doc",
       downloaded 2015-07-18 from
       http://www.kuka.be/main/cservice/faqs/hardware/DefaultColorsRobotAndController.pdf

       all RAL colours converted using http://www.visual-graphics.de/en/customer-care/ral-colours
  -->
  <link name="base_link">
    <visual>
      <origin rpy="0 0 0" xyz="0 0 0"/>
      <geometry>
        <mesh filename="package://kuka_kr10_support/meshes/kr10r1100sixx/visual/base.dae"/>
      </geometry>
      <material name="">
        <color rgba="0.0549019607843 0.0549019607843 0.0627450980392 1.0"/>
      </material>
    </visual>
    <collision>
      <origin rpy="0 0 0" xyz="0 0 0"/>
      <geometry>
        <mesh filename="package://kuka_kr10_support/meshes/kr10r1100sixx/collision/base.stl"/>
      </geometry>
    </collision>
  </link>
  <link name="link_1">
    <visual>
      <origin rpy="0 0 0" xyz="0 0 0"/>
      <geometry>
        <mesh filename="package://kuka_kr10_support/meshes/kr10r1100sixx/visual/link_1.dae"/>
      </geometry>
      <material name="">
        <color rgba="0.964705882353 0.470588235294 0.156862745098 1.0"/>
      </material>
    </visual>
    <collision>
      <origin rpy="0 0 0" xyz="0 0 0"/>
      <geometry>
        <mesh filename="package://kuka_kr10_support/meshes/kr10r1100sixx/collision/link_1.stl"/>
      </geometry>
    </collision>
         <inertial>
            <origin xyz="0 0 0" rpy="0 0 0" />
            <mass value="10.0" />
            <inertia ixx="1.24" ixy="-0.000146" ixz="-0.0353" iyy="1.19" iyz="-0.00761" izz="0.0912" />
          </inertial>
  </link>
  <link name="link_2">
    <visual>
      <origin rpy="0 0 0" xyz="0 0 0"/>
      <geometry>
        <mesh filename="package://kuka_kr10_support/meshes/kr10r1100sixx/visual/link_2.dae"/>
      </geometry>
      <material name="">
        <color rgba="0.964705882353 0.470588235294 0.156862745098 1.0"/>
      </material>
    </visual>
    <collision>
      <origin rpy="0 0 0" xyz="0 0 0"/>
      <geometry>
        <mesh filename="package://kuka_kr10_support/meshes/kr10r1100sixx/collision/link_2.stl"/>
      </geometry>
    </collision>
      <inertial>
        <origin xyz="0 0 0" rpy="0 0 0" />
        <mass value="16.2" />
        <inertia ixx="7.81" ixy="0.00140" ixz="-0.176" iyy="7.78" iyz="0.0459" izz="0.0767" />
      </inertial>
  </link>
  <link name="link_3">
    <visual>
      <origin rpy="0 0 0" xyz="0 0 0"/>
      <geometry>
        <mesh filename="package://kuka_kr10_support/meshes/kr10r1100sixx/visual/link_3.dae"/>
      </geometry>
      <material name="">
        <color rgba="0.964705882353 0.470588235294 0.156862745098 1.0"/>
      </material>
    </visual>
    <collision>
      <origin rpy="0 0 0" xyz="0 0 0"/>
      <geometry>
        <mesh filename="package://kuka_kr10_support/meshes/kr10r1100sixx/collision/link_3.stl"/>
      </geometry>
    </collision>
      <inertial>
        <origin xyz="0 0 0" rpy="0 0 0" />
        <mass value="4.62" />
        <inertia ixx="4.37" ixy="-0.00000359" ixz="-0.186" iyy="4.38" iyz="-0.000112" izz="0.0236" />
      </inertial>
  </link>
  <link name="link_4">
    <visual>
      <origin rpy="0 0 0" xyz="0 0 0"/>
      <geometry>
        <mesh filename="package://kuka_kr10_support/meshes/kr10r1100sixx/visual/link_4.dae"/>
      </geometry>
      <material name="">
        <color rgba="0.964705882353 0.470588235294 0.156862745098 1.0"/>
      </material>
    </visual>
    <collision>
      <origin rpy="0 0 0" xyz="0 0 0"/>
      <geometry>
        <mesh filename="package://kuka_kr10_support/meshes/kr10r1100sixx/collision/link_4.stl"/>
      </geometry>
    </collision>
      <inertial>
        <origin xyz="0 0 0" rpy="0 0 0" />
        <mass value="6.47" />
        <inertia ixx="6.42" ixy="0.00101" ixz="-2.11" iyy="7.18" iyz="0.00229" izz="0.774" />
      </inertial>
  </link>
  <link name="link_5">
    <visual>
      <origin rpy="0 0 0" xyz="0 0 0"/>
      <geometry>
        <mesh filename="package://kuka_kr10_support/meshes/kr10r1100sixx/visual/link_5.dae"/>
      </geometry>
      <material name="">
        <color rgba="0.964705882353 0.470588235294 0.156862745098 1.0"/>
      </material>
    </visual>
    <collision>
      <origin rpy="0 0 0" xyz="0 0 0"/>
      <geometry>
        <mesh filename="package://kuka_kr10_support/meshes/kr10r1100sixx/collision/link_5.stl"/>
      </geometry>
    </collision>
    <inertial>
        <origin xyz="0 0 0" rpy="0 0 0" />
        <mass value="0.711" />
        <inertia ixx="0.704" ixy="-0.000729" ixz="-0.393" iyy="0.924" iyz="-0.00135" izz="0.221" />
      </inertial>
  </link>
  <link name="link_6">
    <visual>
      <origin rpy="0 0 0" xyz="0 0 0"/>
      <geometry>
        <mesh filename="package://kuka_kr10_support/meshes/kr10r1100sixx/visual/link_6.dae"/>
      </geometry>
      <material name="">
        <color rgba="0.505882352941 0.470588235294 0.388235294118 1.0"/>
      </material>
    </visual>
    <collision>
      <origin rpy="0 0 0" xyz="0 0 0"/>
      <geometry>
        <mesh filename="package://kuka_kr10_support/meshes/kr10r1100sixx/collision/link_6.stl"/>
      </geometry>
    </collision>
    <inertial>
      <origin xyz="0 0 0" rpy="0 0 0" />
      <mass value="0.0225" />
      <inertia ixx="0.0223" ixy="0.0" ixz="-0.0137" iyy="0.0307" iyz="0.0" izz="0.00844" />
    </inertial>
  </link>
  <joint name="joint_a1" type="revolute">
    <origin rpy="0 0 0" xyz="0 0 0.400"/>
    <parent link="base_link"/>
    <child link="link_1"/>
    <axis xyz="0 0 -1"/>
    <limit effort="0" lower="-2.26892802759" upper="2.26892802759" velocity="6.28318530718"/>
  </joint>
  <joint name="joint_a2" type="revolute">
    <origin rpy="0 0 0" xyz="0.025 0 0"/>
    <parent link="link_1"/>
    <child link="link_2"/>
    <axis xyz="0 1 0"/>
    <limit effort="0" lower="-3.31612557879" upper="0.785398163397" velocity="5.23598775598"/>
  </joint>
  <joint name="joint_a3" type="revolute">
    <origin rpy="0 0 0" xyz="0.560 0 0"/>
    <parent link="link_2"/>
    <child link="link_3"/>
    <axis xyz="0 1 0"/>
    <limit effort="0" lower="-2.09439510239" upper="2.72271363311" velocity="6.28318530718"/>
  </joint>
  <joint name="joint_a4" type="revolute">
    <origin rpy="0 0 0" xyz="0 0 0.035"/>
    <parent link="link_3"/>
    <child link="link_4"/>
    <axis xyz="-1 0 0"/>
    <limit effort="0" lower="-3.22885911619" upper="3.22885911619" velocity="6.6497044501"/>
  </joint>
  <joint name="joint_a5" type="revolute">
    <origin rpy="0 0 0" xyz="0.515 0 0"/>
    <parent link="link_4"/>
    <child link="link_5"/>
    <axis xyz="0 1 0"/>
    <limit effort="0" lower="-2.09439510239" upper="2.09439510239" velocity="6.77187749774"/>
  </joint>
  <joint name="joint_a6" type="revolute">
    <origin rpy="0 0 0" xyz="0.080 0 0"/>
    <parent link="link_5"/>
    <child link="link_6"/>
    <axis xyz="-1 0 0"/>
    <limit effort="0" lower="-6.10865238198" upper="6.10865238198" velocity="10.7337748998"/>
  </joint>
  <joint name="ee_fixed_joint" type="fixed">
    <parent link="link_6"/>
    <child link="ee_link"/>
    <origin rpy="0.0 -1.57079632679 0" xyz="0.1 0 0.2"/>
  </joint>
  <link name="ee_link"/>
  <!-- ROS base_link to KUKA $ROBROOT coordinate system transform -->
  <link name="base"/>
  <joint name="base_link-base" type="fixed">
    <origin rpy="0 0 0" xyz="0 0 0"/>
    <parent link="base_link"/>
    <child link="base"/>
  </joint>
  <!-- This frame corresponds to the $FLANGE coordinate system in KUKA KRC controllers. -->
  <link name="tool1">
    <visual>
      <origin rpy="0 0 0" xyz="0 0 0"/>
      <geometry>
        <mesh filename="package://kuka_kr10_support/meshes/kr10r1100sixx/visual/KukaFullModel.dae"/>
        <!--<mesh filename="package://kuka_kr10_support/meshes/kr10r1100sixx/collision/KukaFullModel.stl" />  add ${DEG2RAD * 90} z-->
      </geometry>
      <material name="">
        <color rgba="0.505882352941 0.470588235294 0.388235294118 1.0"/>
      </material>
    </visual>
    <!---->
    <collision>
      <origin rpy="0 0 1.57079632679" xyz="0 0 0"/>
      <geometry>
        <mesh filename="package://kuka_kr10_support/meshes/kr10r1100sixx/collision/KukaFullModel.stl"/>
      </geometry>
    </collision>
  </link>
  <joint name="joint_a6-tool1" type="fixed">
    <parent link="link_6"/>
    <child link="tool1"/>
    <origin rpy="0 0 1.57079632679 " xyz="0 0 0"/>
  </joint>
  <!-- marker on robot -->
  <link name="ar_marker_link"/>
  <joint name="ar_marker_joint" type="fixed">
    <parent link="link_6"/>
    <child link="ar_marker_link"/>
    <origin rpy=" 0.349065850399 0.0  -1.57079632679" xyz="0.13335 0 -0.04435 "/>
  </joint>
  <!--

translation:
  x: -0.0126002452514
  y: -0.32461748713
  z: 0.0437622202773
rotation:
  x: -0.500050555084
  y: 0.238977222986
  z: -0.378310686881
  w: 0.74143128707

-->
  <link name="Camera_0_link"/>
  <joint name="Camera_0_joint" type="fixed">
    <parent link="base_link"/>
    <child link="Camera_0_link"/>
    <origin rpy="0.990183934541 1.41532643477 1.17670766228" xyz="-0.0167210220994 0.312384199593 0.0590624174009">
   </origin>
  </joint>
  <link name="Camera_1_link"/>
  <joint name="Camera_1_joint" type="fixed">
    <parent link="base_link"/>
    <child link="Camera_1_link"/>
    <origin rpy="0.990183934541 1.41532643477 1.17670766228" xyz="-0.0167210220994 0.312384199593 0.0590624174009">
      <!--
   <The data was changed on[23.07.18 ; 10:37:21] from: <origin rpy="2.30469203754 0.0 0.0" xyz="-0.0381365999727 -0.201715651512 0.258592534615-->
    </origin>
  </joint>
  <link name="Camera_2_link"/>
  <joint name="Camera_2_joint" type="fixed">
    <parent link="base_link"/>
    <child link="Camera_2_link"/>
    <origin rpy="0.990183934541 1.41532643477 1.17670766228" xyz="-0.0167210220994 0.312384199593 0.0590624174009">
   </origin>
  </joint>
  <link name="Camera_3_link"/>
  <joint name="Camera_3_joint" type="fixed">
    <parent link="base_link"/>
    <child link="Camera_3_link"/>
    <origin rpy="0.990183934541 1.41532643477 1.17670766228" xyz="-0.0167210220994 0.312384199593 0.0590624174009">
   </origin>
  </joint>
  <link name="bottom_link">
    <visual>
      <origin rpy="0 0 0" xyz=" 0 0 0"/>
      <geometry>
        <box size="0.6 0.6 0.76"/>
      </geometry>
      <material name="">
        <color rgba="0.505882352941 0.470588235294 0.388235294118 1.0"/>
      </material>
    </visual>
    <collision>
      <origin rpy="0 0 0" xyz=" 0 0 0"/>
      <geometry>
        <box size="0.6 0.6 0.76"/>
      </geometry>
    </collision>
    &gt;


  </link>
  <joint name="bottom_joint" type="fixed">
    <origin rpy="0 0 0" xyz="0 0 -0.38"/>
    <parent link="base_link"/>
    <child link="bottom_link"/>
  </joint>
</robot>

